start-time: 2022-07-14 22:01:58.232419

Environment:
               test-name: PPMacro
            test-dirpath: /home/alain/Surelog/tests/PPMacro
           test-filepath: /home/alain/Surelog/tests/PPMacro/PPMacro.sl
       workspace-dirpath: /home/alain/Surelog
        surelog-filepath: /home/alain/Surelog/tests/NameCollisionBind/bin/surelog
      uhdm_dump-filepath: /home/alain/Surelog/tests/NameCollisionBind/third_party/UHDM/bin/uhdm-dump
          uvm-reldirpath: ../../third_party/UVM
          output-dirpath: /home/alain/Surelog/tests/NameCollisionBind/regression/PPMacro
     golden-log-filepath: /home/alain/Surelog/tests/PPMacro/PPMacro.log
    surelog-log-filepath: /home/alain/Surelog/tests/NameCollisionBind/regression/PPMacro/PPMacro.log
  uhdm-slpp_all-filepath: /home/alain/Surelog/tests/NameCollisionBind/regression/PPMacro/slpp_all/surelog.uhdm
 uhdm-slpp_unit-filepath: /home/alain/Surelog/tests/NameCollisionBind/regression/PPMacro/slpp_unit/surelog.uhdm
  uhdm-dump-log-filepath: /home/alain/Surelog/tests/NameCollisionBind/regression/PPMacro/uhdm.dump
roundtrip-output-dirpath: /home/alain/Surelog/tests/NameCollisionBind/regression/PPMacro/roundtrip
  roundtrip_log_filepath: /home/alain/Surelog/tests/NameCollisionBind/regression/PPMacro/roundtrip/roundtrip.log
                    tool: None


Snapshot ...
Found 4 files & directories


Running Surelog ...
start-time: 2022-07-14 22:01:58.233135
Loaded command line: -parse dut.sv -nobuiltin -d ast -elabuhdm -d uhdm
Processed command line: -parse dut.sv -nobuiltin -d ast -elabuhdm -d uhdm -mt 0 -mp 0 -o ../NameCollisionBind/regression/PPMacro
Launching surelog with arguments:
['/home/alain/Surelog/tests/NameCollisionBind/bin/surelog',
 '-parse',
 'dut.sv',
 '-nobuiltin',
 '-d',
 'ast',
 '-elabuhdm',
 '-d',
 'uhdm',
 '-mt',
 '0',
 '-mp',
 '0',
 '-o',
 '../NameCollisionBind/regression/PPMacro']


Surelog threw an exception
Traceback (most recent call last):
  File "/home/alain/Surelog/scripts/regression.py", line 347, in _run_surelog
    process = subprocess.Popen(
  File "/usr/lib/python3.9/subprocess.py", line 951, in __init__
    self._execute_child(args, executable, preexec_fn, close_fds,
  File "/usr/lib/python3.9/subprocess.py", line 1821, in _execute_child
    raise child_exception_type(errno_num, err_msg, err_filename)
FileNotFoundError: [Errno 2] No such file or directory: '/home/alain/Surelog/tests/NameCollisionBind/bin/surelog'
end-time: 2022-07-14 22:01:58.234512 0:00:00.001377


Normalizing surelog log file /home/alain/Surelog/tests/NameCollisionBind/regression/PPMacro/PPMacro.log


Restoring pristine state ...
Found 4 files & directories


end-time: 2022-07-14 22:01:58.235193 0:00:00.002774
