start-time: 2022-07-14 22:01:58.090882

Environment:
               test-name: Compl1001
            test-dirpath: /home/alain/Surelog/third_party/tests/Compl1001
           test-filepath: /home/alain/Surelog/third_party/tests/Compl1001/Compl1001.sl
       workspace-dirpath: /home/alain/Surelog
        surelog-filepath: /home/alain/Surelog/tests/NameCollisionBind/bin/surelog
      uhdm_dump-filepath: /home/alain/Surelog/tests/NameCollisionBind/third_party/UHDM/bin/uhdm-dump
          uvm-reldirpath: ../../UVM
          output-dirpath: /home/alain/Surelog/tests/NameCollisionBind/regression/Compl1001
     golden-log-filepath: /home/alain/Surelog/third_party/tests/Compl1001/Compl1001.log
    surelog-log-filepath: /home/alain/Surelog/tests/NameCollisionBind/regression/Compl1001/Compl1001.log
  uhdm-slpp_all-filepath: /home/alain/Surelog/tests/NameCollisionBind/regression/Compl1001/slpp_all/surelog.uhdm
 uhdm-slpp_unit-filepath: /home/alain/Surelog/tests/NameCollisionBind/regression/Compl1001/slpp_unit/surelog.uhdm
  uhdm-dump-log-filepath: /home/alain/Surelog/tests/NameCollisionBind/regression/Compl1001/uhdm.dump
roundtrip-output-dirpath: /home/alain/Surelog/tests/NameCollisionBind/regression/Compl1001/roundtrip
  roundtrip_log_filepath: /home/alain/Surelog/tests/NameCollisionBind/regression/Compl1001/roundtrip/roundtrip.log
                    tool: None


Snapshot ...
Found 4 files & directories


Running Surelog ...
start-time: 2022-07-14 22:01:58.091367
Loaded command line: -parse comp1001.v
Processed command line: -parse comp1001.v -mt 0 -mp 0 -o ../../../tests/NameCollisionBind/regression/Compl1001
Launching surelog with arguments:
['/home/alain/Surelog/tests/NameCollisionBind/bin/surelog',
 '-parse',
 'comp1001.v',
 '-mt',
 '0',
 '-mp',
 '0',
 '-o',
 '../../../tests/NameCollisionBind/regression/Compl1001']


Surelog threw an exception
Traceback (most recent call last):
  File "/home/alain/Surelog/scripts/regression.py", line 347, in _run_surelog
    process = subprocess.Popen(
  File "/usr/lib/python3.9/subprocess.py", line 951, in __init__
    self._execute_child(args, executable, preexec_fn, close_fds,
  File "/usr/lib/python3.9/subprocess.py", line 1821, in _execute_child
    raise child_exception_type(errno_num, err_msg, err_filename)
FileNotFoundError: [Errno 2] No such file or directory: '/home/alain/Surelog/tests/NameCollisionBind/bin/surelog'
end-time: 2022-07-14 22:01:58.092723 0:00:00.001356


Normalizing surelog log file /home/alain/Surelog/tests/NameCollisionBind/regression/Compl1001/Compl1001.log


Restoring pristine state ...
Found 4 files & directories


end-time: 2022-07-14 22:01:58.093047 0:00:00.002165
