start-time: 2022-07-14 22:01:58.319660

Environment:
               test-name: YosysTests
            test-dirpath: /home/alain/Surelog/third_party/tests/YosysTests
           test-filepath: /home/alain/Surelog/third_party/tests/YosysTests/YosysTests.sl
       workspace-dirpath: /home/alain/Surelog
        surelog-filepath: /home/alain/Surelog/tests/NameCollisionBind/bin/surelog
      uhdm_dump-filepath: /home/alain/Surelog/tests/NameCollisionBind/third_party/UHDM/bin/uhdm-dump
          uvm-reldirpath: ../../UVM
          output-dirpath: /home/alain/Surelog/tests/NameCollisionBind/regression/YosysTests
     golden-log-filepath: /home/alain/Surelog/third_party/tests/YosysTests/YosysTests.log
    surelog-log-filepath: /home/alain/Surelog/tests/NameCollisionBind/regression/YosysTests/YosysTests.log
  uhdm-slpp_all-filepath: /home/alain/Surelog/tests/NameCollisionBind/regression/YosysTests/slpp_all/surelog.uhdm
 uhdm-slpp_unit-filepath: /home/alain/Surelog/tests/NameCollisionBind/regression/YosysTests/slpp_unit/surelog.uhdm
  uhdm-dump-log-filepath: /home/alain/Surelog/tests/NameCollisionBind/regression/YosysTests/uhdm.dump
roundtrip-output-dirpath: /home/alain/Surelog/tests/NameCollisionBind/regression/YosysTests/roundtrip
  roundtrip_log_filepath: /home/alain/Surelog/tests/NameCollisionBind/regression/YosysTests/roundtrip/roundtrip.log
                    tool: None


Snapshot ...
Found 5262 files & directories


Running Surelog ...
start-time: 2022-07-14 22:01:58.354330
Loaded command line: -batch batch.txt
Processed command line: -batch batch.txt -mt 0 -mp 0 -o ../../../tests/NameCollisionBind/regression/YosysTests
Launching surelog with arguments:
['/home/alain/Surelog/tests/NameCollisionBind/bin/surelog',
 '-batch',
 'batch.txt',
 '-mt',
 '0',
 '-mp',
 '0',
 '-o',
 '../../../tests/NameCollisionBind/regression/YosysTests']


Surelog threw an exception
Traceback (most recent call last):
  File "/home/alain/Surelog/scripts/regression.py", line 347, in _run_surelog
    process = subprocess.Popen(
  File "/usr/lib/python3.9/subprocess.py", line 951, in __init__
    self._execute_child(args, executable, preexec_fn, close_fds,
  File "/usr/lib/python3.9/subprocess.py", line 1821, in _execute_child
    raise child_exception_type(errno_num, err_msg, err_filename)
FileNotFoundError: [Errno 2] No such file or directory: '/home/alain/Surelog/tests/NameCollisionBind/bin/surelog'
end-time: 2022-07-14 22:01:58.355488 0:00:00.001158


Normalizing surelog log file /home/alain/Surelog/tests/NameCollisionBind/regression/YosysTests/YosysTests.log


Restoring pristine state ...
Found 5262 files & directories


end-time: 2022-07-14 22:01:58.378734 0:00:00.059074
